<?xml version="1.0" ?>
<robot name="BB">
  <link name="Base_1">
    <visual name="Base_1_visual">
      <origin xyz="0 0 0" rpy="0 0 0"/>
      <geometry>
        <mesh filename="meshes/Base_1.stl"/>
      </geometry>
      <material name="Base_1-material">
        <color rgba="0 0 0 1"/>
      </material>
    </visual>
    <collision name="Base_1_collision">
      <origin xyz="0 0 0" rpy="0 0 0"/>
      <geometry>
        <mesh filename="meshes/Base_1.stl"/>
      </geometry>
    </collision>
    <inertial>
      <mass value="2.3364921"/>
      <inertia ixx="0.0072063812" iyy="0.0074640621" izz="0.0043991984" ixy="0" ixz="0" iyz="1.9243429e-05"/>
      <origin xyz="5.5369779e-18 -9.2276364e-05 0.078246001" rpy="0 0 0"/>
    </inertial>
  </link>
  <link name="Left_wheel_1">
    <visual name="Left_wheel_1_visual">
      <origin xyz="0 0 0" rpy="0 0 0"/>
      <geometry>
        <mesh filename="meshes/Left_wheel_1.stl"/>
      </geometry>
      <material name="Left_wheel_1-material">
        <color rgba="1 0 0.5 1"/>
      </material>
    </visual>
    <collision name="Left_wheel_1_collision">
      <origin xyz="0 0 0" rpy="0 0 0"/>
      <geometry>
        <mesh filename="meshes/Left_wheel_1.stl"/>
      </geometry>
    </collision>
    <inertial>
      <mass value="0.038740401"/>
      <inertia ixx="3.603685e-05" iyy="3.603685e-05" izz="7.1660468e-05" ixy="0" ixz="0" iyz="0"/>
      <origin xyz="9.448307e-18 1.5612511e-17 -0.004" rpy="0 0 0"/>
    </inertial>
  </link>
  <link name="Right_wheel_1">
    <visual name="Right_wheel_1_visual">
      <origin xyz="0 0 0" rpy="0 0 0"/>
      <geometry>
        <mesh filename="meshes/Right_wheel_1.stl"/>
      </geometry>
      <material name="Right_wheel_1-material">
        <color rgba="0 1 1 1"/>
      </material>
    </visual>
    <collision name="Right_wheel_1_collision">
      <origin xyz="0 0 0" rpy="0 0 0"/>
      <geometry>
        <mesh filename="meshes/Right_wheel_1.stl"/>
      </geometry>
    </collision>
    <inertial>
      <mass value="0.038740401"/>
      <inertia ixx="3.603685e-05" iyy="3.603685e-05" izz="7.1660468e-05" ixy="0" ixz="0" iyz="0"/>
      <origin xyz="9.5435262e-18 -1.2143064e-17 -0.004" rpy="0 0 0"/>
    </inertial>
  </link>
  <joint name="Left_wheel_joint" type="revolute">
    <origin xyz="0.08 0 0.01" rpy="1.5707963 0 1.5707963"/>
    <parent link="Base_1"/>
    <child link="Left_wheel_1"/>
    <axis xyz="0 0 -1"/>
    <limit effort="1" velocity="1" lower="-6.2831853" upper="6.2831853"/>
  </joint>
  <joint name="Right_wheel_joint" type="revolute">
    <origin xyz="-0.08 0 0.01" rpy="-1.5707963 0 1.5707963"/>
    <parent link="Base_1"/>
    <child link="Right_wheel_1"/>
    <axis xyz="0 0 -1"/>
    <limit effort="1" velocity="1" lower="-6.2831853" upper="6.2831853"/>
  </joint>
</robot>
